Workbook

Sheet Summary
B2: VenQore POS — Settings Functionality Audit
B3: Every setting audited against the live codebase: does it save, does it load back, and does anything real actually read it?
B5: Overall Stats
B6: Total settings audited | E6: =COUNTA('Full Audit'!E2:E1000) -> 132
B7: Average working score (all settings) | E7: =ROUND(AVERAGE('Full Audit'!I2:I1000),0)&"%" -> 53%
B8: Fully Working (score >= 80) | E8: =COUNTIF('Full Audit'!I2:I1000,">=80") -> 61
B9: Partially Working / Unverified (40-79) | E9: =COUNTIFS('Full Audit'!I2:I1000,">=40",'Full Audit'!I2:I1000,"<80") -> 19
B10: Cosmetic Only / Broken / Dead (< 40) | E10: =COUNTIF('Full Audit'!I2:I1000,"<40") -> 51
B12: By Section (average working score)
B13: Tab / Section | C13: Avg. Score | D13: # Settings
B14: Business Info | C14: =ROUND(AVERAGEIF('Full Audit'!B2:B1000,B14,'Full Audit'!I2:I1000),0)&"%" -> 71% | D14: =COUNTIF('Full Audit'!B2:B1000,B14) -> 8
B15: Preferences | C15: =ROUND(AVERAGEIF('Full Audit'!B2:B1000,B15,'Full Audit'!I2:I1000),0)&"%" -> 55% | D15: =COUNTIF('Full Audit'!B2:B1000,B15) -> 12
B16: Sales & Invoicing | C16: =ROUND(AVERAGEIF('Full Audit'!B2:B1000,B16,'Full Audit'!I2:I1000),0)&"%" -> 53% | D16: =COUNTIF('Full Audit'!B2:B1000,B16) -> 17
B17: Taxes | C17: =ROUND(AVERAGEIF('Full Audit'!B2:B1000,B17,'Full Audit'!I2:I1000),0)&"%" -> 43% | D17: =COUNTIF('Full Audit'!B2:B1000,B17) -> 2
B18: Print | C18: =ROUND(AVERAGEIF('Full Audit'!B2:B1000,B18,'Full Audit'!I2:I1000),0)&"%" -> 61% | D18: =COUNTIF('Full Audit'!B2:B1000,B18) -> 60
B19: Messages | C19: =ROUND(AVERAGEIF('Full Audit'!B2:B1000,B19,'Full Audit'!I2:I1000),0)&"%" -> 5% | D19: =COUNTIF('Full Audit'!B2:B1000,B19) -> 6
B20: Party | C20: =ROUND(AVERAGEIF('Full Audit'!B2:B1000,B20,'Full Audit'!I2:I1000),0)&"%" -> 43% | D20: =COUNTIF('Full Audit'!B2:B1000,B20) -> 4
B21: Item | C21: =ROUND(AVERAGEIF('Full Audit'!B2:B1000,B21,'Full Audit'!I2:I1000),0)&"%" -> 60% | D21: =COUNTIF('Full Audit'!B2:B1000,B21) -> 5
B22: Reminders | C22: =ROUND(AVERAGEIF('Full Audit'!B2:B1000,B22,'Full Audit'!I2:I1000),0)&"%" -> 40% | D22: =COUNTIF('Full Audit'!B2:B1000,B22) -> 1
B23: Accounting | C23: =ROUND(AVERAGEIF('Full Audit'!B2:B1000,B23,'Full Audit'!I2:I1000),0)&"%" -> 5% | D23: =COUNTIF('Full Audit'!B2:B1000,B23) -> 2
B24: Security | C24: =ROUND(AVERAGEIF('Full Audit'!B2:B1000,B24,'Full Audit'!I2:I1000),0)&"%" -> 50% | D24: =COUNTIF('Full Audit'!B2:B1000,B24) -> 2
B25: AI & Integrations | C25: =ROUND(AVERAGEIF('Full Audit'!B2:B1000,B25,'Full Audit'!I2:I1000),0)&"%" -> 31% | D25: =COUNTIF('Full Audit'!B2:B1000,B25) -> 9
B26: Backup & Data | C26: =ROUND(AVERAGEIF('Full Audit'!B2:B1000,B26,'Full Audit'!I2:I1000),0)&"%" -> 10% | D26: =COUNTIF('Full Audit'!B2:B1000,B26) -> 1
B27: Factory Reset | C27: =ROUND(AVERAGEIF('Full Audit'!B2:B1000,B27,'Full Audit'!I2:I1000),0)&"%" -> 95% | D27: =COUNTIF('Full Audit'!B2:B1000,B27) -> 1
B29: Top Findings
B30: 1. FBR Integration is fully simulated. SaleController really calls FbrService on every sale when the toggle is on, but the real HTTP call to FBR's API is commented out in FbrService.php and replaced with a hardcoded mock 'Success' response, a fake invoice number, and a fake QR-code URL. The sale is then permanently marked is_fbr_reported = true.
B31: 2. The tax rate that actually calculates tax has no UI. Pos.jsx and CreateInvoice.jsx both compute real tax from default_tax_rate, which has zero UI control anywhere. Meanwhile the polished 'Tax Rates' list (GST/VAT names you can add/edit) saves fine but is never read by any calculation.
B32: 3. WooCommerce card in Settings is disconnected from the real WooCommerce integration. The real sync engine (its own controller, jobs, webhook handler, scheduled poller) never reads the woocommerce_url / consumer key / secret fields in Settings -- it has a completely separate connection flow.
B33: 4. 'Automatic Daily Backups' toggle doesn't control any scheduled backup. The only scheduled backup job in routes/console.php runs off Tenant.google_backup_enabled + an OAuth token, not this Setting.
B34: 5. Two-Factor Authentication toggle has no enforcement anywhere in the login flow -- it saves, but provides no real extra security.
B35: 6. Accounting tab (Fiscal Year Start, Double Entry System) doesn't even load back its own saved values on reopen -- both keys are missing from the page's form initializer.
B36: 7. decimal_places is read correctly in ~7 different places (good), but is bypassed by hardcoded .toFixed(4)/.toFixed(2) in Pos.jsx's reverse-calculate-price-from-total inputs (lines 335-345) -- a direct answer to the decimal-consistency question.
B37: 8. Extra Feed (Lines) print setting is wired to the wrong key -- the slider writes thermal_extra_lines, the renderer reads print_feed_lines. Changing it has no visible effect.
B38: 9. billing_type, sale_prefix and purchase_prefix are all real, actively-used settings with no UI control anywhere to change them (can only be edited directly in the database).
B39: 10. ~15 print/thermal fields (print_party_balance, print_received_by, print_delivered_by, print_payment_mode, print_acknowledgement, thermal_custom_chars, thermal_show_mfg_date/size/model/serial, etc.) have no UI control AND are not read by the renderer -- the one backend method that formally defines all of them, SettingsHelper::getPrintSettings(), is itself never called anywhere.

Sheet Full Audit
A1: Category | B1: Tab / Section | C1: Setting | D1: Data Key | E1: Has UI Control? | F1: Saves to DB? | G1: Loads Back on Reopen? | H1: Actually Enforced / Read At | I1: Working % | J1: Verdict | K1: Evidence / Notes
A2: Operations | B2: Sales & Invoicing | C2: FBR Integration (toggle) | D2: fbr_integration | E2: Yes (appears in 2 tabs) | F2: Yes | G2: Yes | H2: SaleController.php line 384 (calls FbrService on every sale when enabled) | I2: 0 | J2: Broken (Simulated) | K2: SEE DEDICATED FINDING: SaleController really does call FbrService::reportSale() on every sale -- but inside FbrService.php the real HTTP call to FBR's API is commented out (lines 62-75) and replaced with a hardcoded mock 'Success' response plus a fake invoice number and fake QR-code URL. The sale record is then permanently marked is_fbr_reported=true. Turning this on does not actually report anything to FBR.
A3: Operations | B3: Sales & Invoicing | C3: FBR POS ID | D3: fbr_pos_id | E3: Yes (2 tabs) | F3: Yes | G3: Yes | H3: FbrService.php constructor | I3: 0 | J3: Broken (Simulated) | K3: Feeds the same simulated call described above.
A4: Operations | B4: Sales & Invoicing | C4: FBR USIN | D4: fbr_usin | E4: Yes (2 tabs) | F4: Yes | G4: Yes | H4: FbrService.php constructor | I4: 0 | J4: Broken (Simulated) | K4: Feeds the same simulated call described above.
A5: Advanced | B5: AI & Integrations | C5: FBR POS Integration (dup. UI) | D5: fbr_integration | E5: Yes (2nd copy of the same toggle) | F5: Yes | G5: Yes | H5: Same simulated FbrService as the Sales & Invoicing copy | I5: 0 | J5: Broken (Simulated) + Duplicated UI | K5: This is the exact same fbr_integration field as the one in Sales & Invoicing, now editable from two different tabs -- and, per the finding above, it only ever triggers a simulated FBR response either way.
A6: Advanced | B6: AI & Integrations | C6: Stripe (Publishable/Secret/Webhook/Enabled) | D6: stripe_publishable_key, stripe_secret_key, stripe_webhook_secret, stripe_enabled | E6: Card shown but explicitly disabled, no input fields | F6: Yes if forced via API | G6: Yes | H6: None found anywhere | I6: 0 | J6: Not Built (honestly labeled) | K6: Explicitly marked 'Upcoming' with a disabled toggle in the UI itself -- this is not a bug, just clearly-labeled unbuilt functionality.
A7: (Backend-only) | B7: n/a | C7: Tenant name-sync target | D7: store_name | E7: No -- the form sends business_name instead | F7: N/A | G7: N/A | H7: AdminController.php tenant-sync block | I7: 0 | J7: Broken (key mismatch) | K7: The Tenant-mirroring code looks for a settings key called store_name to update $tenant->name -- but the live Settings form always sends business_name instead, so this sync path can never fire from the current UI.
A8: Operations | B8: Print | C8: Party Balance | D8: print_party_balance | E8: No UI control found | F8: Yes | G8: Yes | H8: SettingsHelper::getPrintSettings() only (unused method) | I8: 2 | J8: Dead
A9: Operations | B9: Print | C9: Amount Grouping | D9: print_amount_grouping | E9: No UI control found | F9: Yes | G9: Yes | H9: SettingsHelper::getPrintSettings() only (unused method) | I9: 2 | J9: Dead
A10: Operations | B10: Print | C10: Received By (footer) | D10: print_received_by | E10: No UI control found | F10: Yes | G10: Yes | H10: SettingsHelper::getPrintSettings() only (unused method) | I10: 2 | J10: Dead
A11: Operations | B11: Print | C11: Delivered By (footer) | D11: print_delivered_by | E11: No UI control found | F11: Yes | G11: Yes | H11: SettingsHelper::getPrintSettings() only (unused method) | I11: 2 | J11: Dead
A12: Operations | B12: Print | C12: Payment Mode (footer) | D12: print_payment_mode | E12: No UI control found | F12: Yes | G12: Yes | H12: SettingsHelper::getPrintSettings() only (unused method) | I12: 2 | J12: Dead
A13: Operations | B13: Print | C13: Acknowledgement (footer) | D13: print_acknowledgement | E13: No UI control found | F13: Yes | G13: Yes | H13: SettingsHelper::getPrintSettings() only (unused method) | I13: 2 | J13: Dead
A14: Operations | B14: Print | C14: Custom Chars (thermal) | D14: thermal_custom_chars | E14: No UI control found | F14: Yes | G14: Yes | H14: SettingsHelper::getPrintSettings() only (unused method) | I14: 2 | J14: Dead
A15: Operations | B15: Print | C15: Show MFG Date | D15: thermal_show_mfg_date | E15: No UI control found | F15: Yes | G15: Yes | H15: SettingsHelper::getPrintSettings() only (unused method) | I15: 2 | J15: Dead
A16: Operations | B16: Print | C16: Show Size | D16: thermal_show_size | E16: No UI control found | F16: Yes | G16: Yes | H16: SettingsHelper::getPrintSettings() only (unused method) | I16: 2 | J16: Dead
A17: Operations | B17: Print | C17: Show Model | D17: thermal_show_model | E17: No UI control found | F17: Yes | G17: Yes | H17: SettingsHelper::getPrintSettings() only (unused method) | I17: 2 | J17: Dead
A18: Operations | B18: Print | C18: Show Serial (product) | D18: thermal_show_serial | E18: No UI control found | F18: Yes | G18: Yes | H18: SettingsHelper::getPrintSettings() only (unused method) | I18: 2 | J18: Dead
A19: Organization | B19: Preferences | C19: Multi-Firm Mode | D19: multi_firm_enabled | E19: Yes | F19: Yes | G19: Yes | H19: None found anywhere in app/ or resources/js/ outside the toggle itself | I19: 5 | J19: Cosmetic Only | K19: Zero backend or other frontend consumption found. Real multi-store support is handled entirely by the separate Tenant/TenantUser system described in CLAUDE.md -- unrelated to this toggle.
A20: Operations | B20: Print | C20: Extra Top Space | D20: print_extra_space_top | E20: No UI control found | F20: Yes | G20: Yes | H20: SettingsHelper::getPrintSettings() only -- and that method itself is never called anywhere | I20: 5 | J20: Dead
A21: Operations | B21: Print | C21: Min Item Rows | D21: print_min_item_rows | E21: No UI control found | F21: Yes | G21: Yes | H21: SettingsHelper::getPrintSettings() only (unused method) | I21: 5 | J21: Dead
A22: Operations | B22: Print | C22: Description (footer, distinct key) | D22: print_description | E22: No UI control found (print_show_description is the one with UI) | F22: Yes | G22: Yes | H22: SettingsHelper::getPrintSettings() only | I22: 5 | J22: Dead / confusing duplicate name | K22: A second, differently-named key that looks like a duplicate of print_show_description but has no UI and no renderer consumer.
A23: Operations | B23: Messages | C23: Enable WhatsApp | D23: whatsapp_enabled | E23: Yes | F23: Yes | G23: Yes | H23: None found anywhere in app/ | I23: 5 | J23: Cosmetic Only | K23: No WhatsApp-sending service exists anywhere in the backend. The 'Connect Account' button next to this card has no onClick handler at all.
A24: Operations | B24: Messages | C24: WhatsApp API URL | D24: whatsapp_api_url | E24: Yes | F24: Yes | G24: Yes | H24: None found | I24: 5 | J24: Cosmetic Only
A25: Operations | B25: Messages | C25: WhatsApp Access Token | D25: whatsapp_access_token | E25: Yes | F25: Yes | G25: Yes | H25: None found | I25: 5 | J25: Cosmetic Only
A26: Operations | B26: Messages | C26: WhatsApp Phone Number ID | D26: whatsapp_phone_number_id | E26: Yes | F26: Yes | G26: Yes | H26: None found | I26: 5 | J26: Cosmetic Only
A27: Operations | B27: Messages | C27: Send SMS to Party | D27: sms_to_party | E27: Yes | F27: Yes | G27: Yes | H27: None found | I27: 5 | J27: Cosmetic Only | K27: No SMS-sending service exists anywhere in the backend.
A28: Operations | B28: Messages | C28: Auto-send for Sales | D28: auto_send_sales | E28: Yes | F28: Yes | G28: Yes | H28: None found | I28: 5 | J28: Cosmetic Only
A29: Operations | B29: Party | C29: Enable Credit Limit | D29: enable_credit_limit | E29: Yes | F29: Yes | G29: Yes | H29: None found -- Party model has no credit_limit field at all | I29: 5 | J29: Cosmetic Only | K29: Confirmed: no credit_limit column/logic anywhere on the Party model.
A30: Operations | B30: Accounting | C30: Fiscal Year Start | D30: fiscal_year_start | E30: Yes | F30: Yes | G30: No | H30: None found anywhere in app/ | I30: 5 | J30: Broken | K30: CONFIRMED BUG: this key is missing from Settings.jsx's useForm initializer entirely, so even after you save a value, reopening Settings always shows the hardcoded 2025-01-01 placeholder, never your real saved value. Not read anywhere in backend accounting logic either.
A31: Operations | B31: Accounting | C31: Double Entry System | D31: enable_double_entry | E31: Yes | F31: Yes | G31: No | H31: None found anywhere in app/ | I31: 5 | J31: Broken | K31: Same load-back bug as Fiscal Year Start -- missing from useForm, always resets visually on reload. Also, per CLAUDE.md, JournalEntry/JournalItem double-entry accounting is already generated automatically on every transaction -- this toggle doesn't gate anything that isn't already unconditionally on.
A32: Advanced | B32: Security | C32: Two-Factor Authentication | D32: two_factor_auth | E32: Yes | F32: Yes | G32: Yes | H32: SettingsHelper::isTwoFactorEnabled() (getter only -- zero references anywhere in app/Http auth/login code) | I32: 5 | J32: Broken / Cosmetic | K32: CONFIRMED: no 2FA code prompt exists anywhere in the login flow. Turning this on saves the setting but provides no additional real security -- a false sense of protection.
A33: Organization | B33: Preferences | C33: Force Dark Mode | D33: dark_mode_default | E33: Yes | F33: Yes | G33: Yes | H33: None found -- ThemeContext.jsx never reads this key | I33: 10 | J33: Broken | K33: Confirmed: the live theme system (Contexts/ThemeContext.jsx) is driven purely by the user's manual Sun/Moon toggle. This setting saves but has no effect on the actual theme shown at login.
A34: Operations | B34: Print | C34: Extra Feed (Lines) | D34: thermal_extra_lines | E34: Yes | F34: Yes | G34: Yes | H34: SettingsHelper::getPrintSettings() only -- PrintPreview.jsx actually reads a DIFFERENT key, print_feed_lines, which has no UI at all | I34: 10 | J34: Broken (key name mismatch) | K34: CONFIRMED BUG: the slider you drag writes thermal_extra_lines, but the renderer that adds blank space at the bottom of a thermal receipt checks data.print_feed_lines instead -- a key that no UI control ever sets. Changing this slider has zero visible effect on a printed receipt.
A35: Operations | B35: Print | C35: Copies to Print | D35: thermal_copies | E35: Yes | F35: Yes | G35: Yes | H35: Not read anywhere in the print-execution path | I35: 10 | J35: Likely Dead | K35: The only print action found (Test Print) uses the browser's native print dialog, which has no hook for a repeat-copy count.
A36: Operations | B36: Print | C36: Auto Cut Paper | D36: thermal_auto_cut | E36: Yes | F36: Yes | G36: Yes | H36: None found | I36: 10 | J36: Likely Dead | K36: This is a hardware-level ESC/POS command; no raw printer-driver code was found anywhere -- only a standard browser print dialog exists in this codebase.
A37: Operations | B37: Print | C37: Open Cash Drawer | D37: thermal_open_drawer | E37: Yes | F37: Yes | G37: Yes | H37: None found | I37: 10 | J37: Likely Dead | K37: Same as Auto Cut Paper -- no hardware command pathway found.
A38: Advanced | B38: AI & Integrations | C38: WooCommerce Store URL | D38: woocommerce_url | E38: Yes (plan-gated) | F38: Yes | G38: Yes | H38: None found anywhere in the real WooSync subsystem (WooConnectionController, SyncEngine, webhook/polling jobs) | I38: 10 | J38: Broken / Disconnected | K38: CONFIRMED: the real, sophisticated WooCommerce integration (its own controller, sync engine, webhook handler and scheduled polling job) never reads this key -- it has an entirely separate connection mechanism (a handshake/OAuth-style flow via WooHandshakeController). This Settings card almost certainly does nothing when filled in.
A39: Advanced | B39: AI & Integrations | C39: WooCommerce Consumer Key | D39: woocommerce_consumer_key | E39: Yes (plan-gated) | F39: Yes | G39: Yes | H39: Same as above | I39: 10 | J39: Broken / Disconnected
A40: Advanced | B40: AI & Integrations | C40: WooCommerce Consumer Secret | D40: woocommerce_consumer_secret | E40: Yes (plan-gated) | F40: Yes | G40: Yes | H40: Same as above | I40: 10 | J40: Broken / Disconnected
...
